Workbook

Sheet Instructivo
A1: Manual del usuario
A3: Por primera vez el termino PEST fue utilizado por Francisco Aguilar en su libro de 1967 «Análisis del entorno empresarial». El acrónimo PEST hace referencia a los Factores Políticos, a los Factores Económicos, a los Factores Sociológicos y a los Factores Tecnológicos que afectan a una compañía desde su macro-entorno. El «EL» a el término PEST, dando lugar al término PESTEL, se añadió por Liam Fahey y V.K. Narayanan en su libro, publicado en 1986, «Análisis Macro-ambiental en Gestión Estratégica». El «EL» añadido a «PEST» hace referencia a los Factores Ecológicos y a los Factores Legales, ambos de creciente importancia en los últimos tiempos.
A5: 1- En el libro áreas, ya están creadas las áreas respectivas, para nuestro caso seis áreas.
A6: 2- Posteriormente, hay unas hojas que inician con la letra F, esto identifica como factor y luego las áreas
A7: 3- En cada hoja de este libro, que incluye factores, podemos eliminar o cambiar aspectos a evaluar en cada factor, no introducimos o cambiamos información en la Matriz Pestel o en el informe final
A8: 4- Los aspectos son medidos en tres dimensiones, la primera dimensión es la importancia, mide que tan importante es el aspecto, que asu vez tiene 5 variables: Sin importancia=1, Poco Importnate=2, Indiferente=3, Importante=4, Muy importante=5 La segunda dimensión es la Intensidad, que tambien es evaluada en 5 variables, y es la que nos indica que tan fuerte o debil es esa intensidad, las 5 variables son: Muy fuerte=5, Fuerte=4, Promedio=3, Debil=2, Muy Debil=1 La tercera dimensión es la Tendencia, que evalua cual va hacer el comportamiento del aspecto: Mejora Mucho=5, Mejora=4, Indiferente=3 Peor=2, Mucho Peor=1
A9: 5- Para hacer dicho análisis, es necesario leer los link que se encuentan en la parte inferior, con esto cerramos lo de la pregunta integradora y hace parte del capitulo de la evaluación de proyectos del Dr. Mauricio Mejía.
A13: https://www.garrigues.com/es_ES/guias/guia-para-hacer-negocios-en-colombia
A15: https://www2.deloitte.com/co/es/pages/tax/articles/doing-bussiness-colombia-2019.html
A17: https://www.pwc.com/co/en/publications/technology/Doing%20Business%202019%20PwC.pdf
A19: https://intelligence.weforum.org/topics/a1Gb0000000pTD7EAM?tab=publications
A21: https://www.colombiaproductiva.com/ptp-capacita/capacitaciones

Sheet Áreas
A1: Políticos
A2: Económicos
A3: Sociales
A4: Tecnológicos
A5: Ambientales
A6: Legales

Sheet F_Pol
C1: Parches - Plataforma de Eventos y Networking
C3: FACTOR POLÍTICO
C6: Aspectos a evaluar en Factores Políticos | D6: ¿Cómo podrán impactar los aspectos listados en cada uno de los factores de la izquierda en su negocio? | E6: Importancia | F6: Marco Temporal | G6: Intensidad | H6: Tipo de tendencia | I6: Puntuación
B7: =I7 -> 100 | C7: Estabilidad política y social en Colombia | D7: La estabilidad política determina el entorno seguro para eventos presenciales y actividades de grupo | E7: Muy importante | F7: Indefinido | G7: Muy fuerte | H7: Mejora | I7: =IF(ISERROR(VLOOKUP(E7,$K$10:$L$14,2,FALSE())*VLOOKUP(G7,$K$18:$L$22,2,FALSE())*VLOOKUP(H7,$K$26:$L$30,2,FALSE())),"",VLOOKUP(E7,$K$10:$L$14,2,FALSE())*VLOOKUP(G7,$K$18:$L$22,2,FALSE())*VLOOKUP(H7,$K$26:$L$30,2,FALSE())) -> 100
B8: =I8 -> 80 | C8: Política digital y regulación de plataformas tech | D8: Regulación gubernamental sobre privacidad biométrica y datos personales que recopila la plataforma | E8: Muy importante | F8: Indefinido | G8: Fuerte | H8: Mejora | I8: =IF(ISERROR(VLOOKUP(E8,$K$10:$L$14,2,FALSE())*VLOOKUP(G8,$K$18:$L$22,2,FALSE())*VLOOKUP(H8,$K$26:$L$30,2,FALSE())),"",VLOOKUP(E8,$K$10:$L$14,2,FALSE())*VLOOKUP(G8,$K$18:$L$22,2,FALSE())*VLOOKUP(H8,$K$26:$L$30,2,FALSE())) -> 80 | K8: Importancia | N8: 0.0002 | O8: =IF(I7="","",I7+N8) -> 100.0002 | P8: =IF(C7=0,"",C7) -> Estabilidad política y social en Colombia | Q8: =I7 -> 100
B9: =I9 -> 64 | C9: Apoyo estatal a emprendimientos digitales y startups | D9: Beneficios fiscales, incubadoras y programas de apoyo a startups tech en Colombia | E9: Importante | F9: Indefinido | G9: Fuerte | H9: Mejora | I9: =IF(ISERROR(VLOOKUP(E9,$K$10:$L$14,2,FALSE())*VLOOKUP(G9,$K$18:$L$22,2,FALSE())*VLOOKUP(H9,$K$26:$L$30,2,FALSE())),"",VLOOKUP(E9,$K$10:$L$14,2,FALSE())*VLOOKUP(G9,$K$18:$L$22,2,FALSE())*VLOOKUP(H9,$K$26:$L$30,2,FALSE())) -> 64 | N9: 0.00019 | O9: =IF(I8="","",I8+N9) -> 80.00019 | P9: =IF(C8=0,"",C8) -> Política digital y regulación de plataformas tech | Q9: =I8 -> 80
B10: =I10 -> 80 | C10: Declaratoria de desastre nacional y capacidad de respuesta institucional | D10: El terremoto de magnitud 7,4 del 10 de agosto de 2026 (Chocó) llevó al Gobierno a declarar desastre nacional; la coordinación de la UNGRD y las alcaldías redefine permisos para aforos y eventos públicos, y prioriza inversión estatal y flexibilidad regulatoria en las zonas afectadas | E10: Muy importante | F10: Definido | G10: Fuerte | H10: Mejora | I10: =IF(ISERROR(VLOOKUP(E10,$K$10:$L$14,2,FALSE())*VLOOKUP(G10,$K$18:$L$22,2,FALSE())*VLOOKUP(H10,$K$26:$L$30,2,FALSE())),"",VLOOKUP(E10,$K$10:$L$14,2,FALSE())*VLOOKUP(G10,$K$18:$L$22,2,FALSE())*VLOOKUP(H10,$K$26:$L$30,2,FALSE())) -> 80 | K10: Sin importancia | L10: 1 | N10: 0.00018 | O10: =IF(I9="","",I9+N10) -> 64.00018 | P10: =IF(C9=0,"",C9) -> Apoyo estatal a emprendimientos digitales y startups | Q10: =I9 -> 64
B11: =I11 -> 0 | C11: P1 | D11: http://www.fao.org/3/j7507s/j7507s10.htm | K11: Poco importante | L11: 2 | N11: 0.00017 | O11: =IF(I10="","",I10+N11) -> 80.00017 | P11: =IF(C10=0,"",C10) -> Declaratoria de desastre nacional y capacidad de respuesta institucional | Q11: =I10 -> 80
B12: =I12 -> 0 | C12: P2 | D12: [https://www.dnp.gov.co/inversiones-y-finanzas-publicas/] | K12: Indiferente | L12: 3 | N12: 0.00016 | O12: =IF(I11="","",I11+N12) | P12: =IF(C11=0,"",C11) -> P1 | Q12: =I11 -> 0
B13: =I13 -> 0 | C13: P3 | D13: [https://transparenciacolombia.org.co/monitor-ciudadano/] | K13: Importante | L13: 4 | N13: 0.00015 | O13: =IF(I12="","",I12+N13) | P13: =IF(C12=0,"",C12) -> P2 | Q13: =I12 -> 0
B14: =I14 -> 0 | K14: Muy importante | L14: 5 | N14: 0.00014 | O14: =IF(I13="","",I13+N14) | P14: =IF(C13=0,"",C13) -> P3 | Q14: =I13 -> 0
B15: =I15 -> 0 | N15: 0.00013 | O15: =IF(I14="","",I14+N15) | P15: =IF(C14=0,"",C14) | Q15: =I14 -> 0
B16: =I16 -> 0 | K16: Intensidad | N16: 0.00012 | O16: =IF(I15="","",I15+N16) | P16: =IF(C15=0,"",C15) | Q16: =I15 -> 0
B17: =I17 | I17: =IF(ISERROR(VLOOKUP(E17,$K$10:$L$14,2,FALSE())*VLOOKUP(G17,$K$18:$L$22,2,FALSE())*VLOOKUP(H17,$K$26:$L$30,2,FALSE())),"",VLOOKUP(E17,$K$10:$L$14,2,FALSE())*VLOOKUP(G17,$K$18:$L$22,2,FALSE())*VLOOKUP(H17,$K$26:$L$30,2,FALSE())) | N17: 0.00011 | O17: =IF(I16="","",I16+N17) | P17: =IF(C16=0,"",C16) | Q17: =I16 -> 0
B18: =I18 | I18: =IF(ISERROR(VLOOKUP(E18,$K$10:$L$14,2,FALSE())*VLOOKUP(G18,$K$18:$L$22,2,FALSE())*VLOOKUP(H18,$K$26:$L$30,2,FALSE())),"",VLOOKUP(E18,$K$10:$L$14,2,FALSE())*VLOOKUP(G18,$K$18:$L$22,2,FALSE())*VLOOKUP(H18,$K$26:$L$30,2,FALSE())) | K18: Muy Fuerte | L18: 5 | N18: 0.0001 | O18: =IF(I17="","",I17+N18) | P18: =IF(C17=0,"",C17) | Q18: =I17
B19: =I19 | I19: =IF(ISERROR(VLOOKUP(E19,$K$10:$L$14,2,FALSE())*VLOOKUP(G19,$K$18:$L$22,2,FALSE())*VLOOKUP(H19,$K$26:$L$30,2,FALSE())),"",VLOOKUP(E19,$K$10:$L$14,2,FALSE())*VLOOKUP(G19,$K$18:$L$22,2,FALSE())*VLOOKUP(H19,$K$26:$L$30,2,FALSE())) | K19: Fuerte | L19: 4 | N19: 9e-05 | O19: =IF(I18="","",I18+N19) | P19: =IF(C18=0,"",C18) | Q19: =I18
B20: =I20 | I20: =IF(ISERROR(VLOOKUP(E20,$K$10:$L$14,2,FALSE())*VLOOKUP(G20,$K$18:$L$22,2,FALSE())*VLOOKUP(H20,$K$26:$L$30,2,FALSE())),"",VLOOKUP(E20,$K$10:$L$14,2,FALSE())*VLOOKUP(G20,$K$18:$L$22,2,FALSE())*VLOOKUP(H20,$K$26:$L$30,2,FALSE())) | K20: Promedio | L20: 3 | N20: 8e-05 | O20: =IF(I19="","",I19+N20) | P20: =IF(C19=0,"",C19) | Q20: =I19
B21: =I21 | I21: =IF(ISERROR(VLOOKUP(E21,$K$10:$L$14,2,FALSE())*VLOOKUP(G21,$K$18:$L$22,2,FALSE())*VLOOKUP(H21,$K$26:$L$30,2,FALSE())),"",VLOOKUP(E21,$K$10:$L$14,2,FALSE())*VLOOKUP(G21,$K$18:$L$22,2,FALSE())*VLOOKUP(H21,$K$26:$L$30,2,FALSE())) | K21: Débil | L21: 2 | N21: 7e-05 | O21: =IF(I20="","",I20+N21) | P21: =IF(C20=0,"",C20) | Q21: =I20
B22: =I22 | I22: =IF(ISERROR(VLOOKUP(E22,$K$10:$L$14,2,FALSE())*VLOOKUP(G22,$K$18:$L$22,2,FALSE())*VLOOKUP(H22,$K$26:$L$30,2,FALSE())),"",VLOOKUP(E22,$K$10:$L$14,2,FALSE())*VLOOKUP(G22,$K$18:$L$22,2,FALSE())*VLOOKUP(H22,$K$26:$L$30,2,FALSE())) | K22: Muy Débil | L22: 1 | N22: 6e-05 | O22: =IF(I21="","",I21+N22) | P22: =IF(C21=0,"",C21) | Q22: =I21
B23: =I23 | I23: =IF(ISERROR(VLOOKUP(E23,$K$10:$L$14,2,FALSE())*VLOOKUP(G23,$K$18:$L$22,2,FALSE())*VLOOKUP(H23,$K$26:$L$30,2,FALSE())),"",VLOOKUP(E23,$K$10:$L$14,2,FALSE())*VLOOKUP(G23,$K$18:$L$22,2,FALSE())*VLOOKUP(H23,$K$26:$L$30,2,FALSE())) | N23: 5e-05 | O23: =IF(I22="","",I22+N23) | P23: =IF(C22=0,"",C22) | Q23: =I22
B24: =I24 | I24: =IF(ISERROR(VLOOKUP(E24,$K$10:$L$14,2,FALSE())*VLOOKUP(G24,$K$18:$L$22,2,FALSE())*VLOOKUP(H24,$K$26:$L$30,2,FALSE())),"",VLOOKUP(E24,$K$10:$L$14,2,FALSE())*VLOOKUP(G24,$K$18:$L$22,2,FALSE())*VLOOKUP(H24,$K$26:$L$30,2,FALSE())) | K24: Tendencia | N24: 4e-05 | O24: =IF(I23="","",I23+N24) | P24: =IF(C23=0,"",C23) | Q24: =I23
B25: =I25 | I25: =IF(ISERROR(VLOOKUP(E25,$K$10:$L$14,2,FALSE())*VLOOKUP(G25,$K$18:$L$22,2,FALSE())*VLOOKUP(H25,$K$26:$L$30,2,FALSE())),"",VLOOKUP(E25,$K$10:$L$14,2,FALSE())*VLOOKUP(G25,$K$18:$L$22,2,FALSE())*VLOOKUP(H25,$K$26:$L$30,2,FALSE())) | N25: 3e-05
B26: =I26 | I26: =IF(ISERROR(VLOOKUP(E26,$K$10:$L$14,2,FALSE())*VLOOKUP(G26,$K$18:$L$22,2,FALSE())*VLOOKUP(H26,$K$26:$L$30,2,FALSE())),"",VLOOKUP(E26,$K$10:$L$14,2,FALSE())*VLOOKUP(G26,$K$18:$L$22,2,FALSE())*VLOOKUP(H26,$K$26:$L$30,2,FALSE())) | K26: Mejora Mucho | L26: 5 | N26: 2e-05 | O26: =IF(I24="","",I24+N26) | P26: =IF(C24=0,"",C24) | Q26: =I24
B27: =I27 | I27: =IF(ISERROR(VLOOKUP(E27,$K$10:$L$14,2,FALSE())*VLOOKUP(G27,$K$18:$L$22,2,FALSE())*VLOOKUP(H27,$K$26:$L$30,2,FALSE())),"",VLOOKUP(E27,$K$10:$L$14,2,FALSE())*VLOOKUP(G27,$K$18:$L$22,2,FALSE())*VLOOKUP(H27,$K$26:$L$30,2,FALSE())) | K27: Mejora | L27: 4 | N27: 1e-05 | O27: =IF(I25="","",I25+N27) | P27: =IF(C25=0,"",C25) | Q27: =I25
B28: =I28 | I28: =IF(ISERROR(VLOOKUP(E28,$K$10:$L$14,2,FALSE())*VLOOKUP(G28,$K$18:$L$22,2,FALSE())*VLOOKUP(H28,$K$26:$L$30,2,FALSE())),"",VLOOKUP(E28,$K$10:$L$14,2,FALSE())*VLOOKUP(G28,$K$18:$L$22,2,FALSE())*VLOOKUP(H28,$K$26:$L$30,2,FALSE())) | K28: Indiferente | L28: 3 | O28: =IF(I26="","",I26+N28) | P28: =IF(C26=0,"",C26) | Q28: =I26
B29: =I29 | I29: =IF(ISERROR(VLOOKUP(E29,$K$10:$L$14,2,FALSE())*VLOOKUP(G29,$K$18:$L$22,2,FALSE())*VLOOKUP(H29,$K$26:$L$30,2,FALSE())),"",VLOOKUP(E29,$K$10:$L$14,2,FALSE())*VLOOKUP(G29,$K$18:$L$22,2,FALSE())*VLOOKUP(H29,$K$26:$L$30,2,FALSE())) | K29: Peor | L29: 2 | O29: =IF(I27="","",I27+N29) | P29: =IF(C27=0,"",C27) | Q29: =I27
B30: =I30 | I30: =IF(ISERROR(VLOOKUP(E30,$K$10:$L$14,2,FALSE())*VLOOKUP(G30,$K$18:$L$22,2,FALSE())*VLOOKUP(H30,$K$26:$L$30,2,FALSE())),"",VLOOKUP(E30,$K$10:$L$14,2,FALSE())*VLOOKUP(G30,$K$18:$L$22,2,FALSE())*VLOOKUP(H30,$K$26:$L$30,2,FALSE())) | K30: Mucho Peor | L30: 1 | O30: =IF(I28="","",I28+N30) | P30: =IF(C28=0,"",C28) | Q30: =I28
C31: La puntuación global de los factores políticos | I31: =SUM(I7:I30) -> 324 | O31: =IF(#REF!="","",#REF!+N31) -> #REF! | P31: =IF(#REF!=0,"",#REF!) -> #REF! | Q31: =#REF! -> #REF!
I32: =IF(ISERROR(VLOOKUP(E32,$K$10:$L$14,2,FALSE())*VLOOKUP(G32,$K$18:$L$22,2,FALSE())*VLOOKUP(H32,$K$26:$L$30,2,FALSE())),"",VLOOKUP(E32,$K$10:$L$14,2,FALSE())*VLOOKUP(G32,$K$18:$L$22,2,FALSE())*VLOOKUP(H32,$K$26:$L$30,2,FALSE())) | K32: Marco temporal | O32: =IF(I31="","",I31+N32) -> 324 | P32: =IF(C31=0,"",C31) -> La puntuación global de los factores políticos | Q32: =I31 -> 324
C33: [https://www.funcionpublica.gov.co/eva/gestornormativo/norma.php?i=39430]
K34: Definido
K35: Indefinido

Sheet F_Eco
C1: Parches - Plataforma de Eventos y Networking
C3: FACTOR ECONÓMICO
C6: Aspectos a evaluar en Factores Económicos | D6: ¿Cómo podrán impactar los aspectos listados en cada uno de los factores de la izquierda en su negocio? | E6: Importancia | F6: Marco Temporal | G6: Intensidad | H6: Tipo de Tendencia | I6: Puntuación
B7: =I7 -> 40 | C7: Poder adquisitivo de jóvenes y profesionales | D7: Capacidad económica del público objetivo para pagar eventos, boletería y actividades | E7: Muy importante | F7: Indefinido | G7: Débil | H7: Mejora | I7: =IF(ISERROR(VLOOKUP(E7,$K$10:$L$14,2,FALSE())*VLOOKUP(G7,$K$18:$L$22,2,FALSE())*VLOOKUP(H7,$K$26:$L$30,2,FALSE())),"",VLOOKUP(E7,$K$10:$L$14,2,FALSE())*VLOOKUP(G7,$K$18:$L$22,2,FALSE())*VLOOKUP(H7,$K$26:$L$30,2,FALSE())) -> 40
B8: =I8 -> 125 | C8: Crecimiento del sector de entretenimiento y ocio | D8: Expansión post-COVID de cines, bares, eventos culturales y experiencias recreativas | E8: Muy importante | F8: Indefinido | G8: Muy fuerte | H8: Mejora mucho | I8: =IF(ISERROR(VLOOKUP(E8,$K$10:$L$14,2,FALSE())*VLOOKUP(G8,$K$18:$L$22,2,FALSE())*VLOOKUP(H8,$K$26:$L$30,2,FALSE())),"",VLOOKUP(E8,$K$10:$L$14,2,FALSE())*VLOOKUP(G8,$K$18:$L$22,2,FALSE())*VLOOKUP(H8,$K$26:$L$30,2,FALSE())) -> 125 | K8: Importancia | N8: 0.0002 | O8: =IF(I7="","",I7+N8) -> 40.0002 | P8: =IF(C7=0,"",C7) -> Poder adquisitivo de jóvenes y profesionales | Q8: =I7 -> 40
B9: =I9 -> 40 | C9: Inflación y variación en costos operacionales | D9: Impacto de la inflación en costos de servidores, integración de APIs y operación general; el terremoto del 10 de agosto de 2026 añade presión adicional (~10 pbs proyectados al cierre de 2026, según Banco de Occidente) por costos de reconstrucción, logística y materiales | E9: Importante | F9: Indefinido | G9: Muy fuerte | H9: Peor | I9: =IF(ISERROR(VLOOKUP(E9,$K$10:$L$14,2,FALSE())*VLOOKUP(G9,$K$18:$L$22,2,FALSE())*VLOOKUP(H9,$K$26:$L$30,2,FALSE())),"",VLOOKUP(E9,$K$10:$L$14,2,FALSE())*VLOOKUP(G9,$K$18:$L$22,2,FALSE())*VLOOKUP(H9,$K$26:$L$30,2,FALSE())) -> 40 | N9: 0.00019 | O9: =IF(I8="","",I8+N9) -> 125.00019 | P9: =IF(C8=0,"",C8) -> Crecimiento del sector de entretenimiento y ocio | Q9: =I8 -> 125
B10: =I10 -> 125 | C10: Integración de pasarelas de pago locales | D10: Disponibilidad de proveedores colombianos (Wompi, PayU, Nequi) para monetización | E10: Muy importante | F10: Indefinido | G10: Muy fuerte | H10: Mejora mucho | I10: =IF(ISERROR(VLOOKUP(E10,$K$10:$L$14,2,FALSE())*VLOOKUP(G10,$K$18:$L$22,2,FALSE())*VLOOKUP(H10,$K$26:$L$30,2,FALSE())),"",VLOOKUP(E10,$K$10:$L$14,2,FALSE())*VLOOKUP(G10,$K$18:$L$22,2,FALSE())*VLOOKUP(H10,$K$26:$L$30,2,FALSE())) -> 125 | K10: Sin importancia | L10: 1 | N10: 0.00018 | O10: =IF(I9="","",I9+N10) -> 40.00018 | P10: =IF(C9=0,"",C9) -> Inflación y variación en costos operacionales | Q10: =I9 -> 40
B11: =I11 -> 0 | C11: E1 | D11: https://www.dane.gov.co/index.php/estadisticas-por-tema/cuentas-nacionales/cuentas-nacionales-trimestrales/pib-informacion-tecnica | K11: Poco importante | L11: 2 | N11: 0.00017 | O11: =IF(I10="","",I10+N11) -> 125.00017 | P11: =IF(C10=0,"",C10) -> Integración de pasarelas de pago locales | Q11: =I10 -> 125
B12: =I12 -> 0 | C12: E2 | D12: https://www.elcolombiano.com/negocios/terremoto-10-agosto-reduciria-pib-colombia-2026-FB40278397 | K12: Indiferente | L12: 3 | N12: 0.00016 | O12: =IF(I11="","",I11+N12) | P12: =IF(C11=0,"",C11) -> E1 | Q12: =I11 -> 0
B13: =I13 -> 0 | C13: E3 | D13: https://colombiafintech.co/contenidos-propios/pagos-digitales-2025/ | K13: Importante | L13: 4 | N13: 0.00015 | O13: =IF(I12="","",I12+N13) | P13: =IF(C12=0,"",C12) -> E2 | Q13: =I12 -> 0
B14: =I14 -> 0 | K14: Muy importante | L14: 5 | N14: 0.00014 | O14: =IF(I13="","",I13+N14) | P14: =IF(C13=0,"",C13) -> E3 | Q14: =I13 -> 0
B15: =I15 -> 0 | N15: 0.00013 | O15: =IF(I14="","",I14+N15) | P15: =IF(C14=0,"",C14) | Q15: =I14 -> 0
B16: =I16 -> 0 | K16: Intensidad | N16: 0.00012 | O16: =IF(I15="","",I15+N16) | P16: =IF(C15=0,"",C15) | Q16: =I15 -> 0
B17: =I17 | I17: =IF(ISERROR(VLOOKUP(E17,$K$10:$L$14,2,FALSE())*VLOOKUP(G17,$K$18:$L$22,2,FALSE())*VLOOKUP(H17,$K$26:$L$30,2,FALSE())),"",VLOOKUP(E17,$K$10:$L$14,2,FALSE())*VLOOKUP(G17,$K$18:$L$22,2,FALSE())*VLOOKUP(H17,$K$26:$L$30,2,FALSE())) | N17: 0.00011 | O17: =IF(I16="","",I16+N17) | P17: =IF(C16=0,"",C16) | Q17: =I16 -> 0
B18: =I18 | I18: =IF(ISERROR(VLOOKUP(E18,$K$10:$L$14,2,FALSE())*VLOOKUP(G18,$K$18:$L$22,2,FALSE())*VLOOKUP(H18,$K$26:$L$30,2,FALSE())),"",VLOOKUP(E18,$K$10:$L$14,2,FALSE())*VLOOKUP(G18,$K$18:$L$22,2,FALSE())*VLOOKUP(H18,$K$26:$L$30,2,FALSE())) | K18: Muy Fuerte | L18: 5 | N18: 0.0001 | O18: =IF(I17="","",I17+N18) | P18: =IF(C17=0,"",C17) | Q18: =I17
B19: =I19 | I19: =IF(ISERROR(VLOOKUP(E19,$K$10:$L$14,2,FALSE())*VLOOKUP(G19,$K$18:$L$22,2,FALSE())*VLOOKUP(H19,$K$26:$L$30,2,FALSE())),"",VLOOKUP(E19,$K$10:$L$14,2,FALSE())*VLOOKUP(G19,$K$18:$L$22,2,FALSE())*VLOOKUP(H19,$K$26:$L$30,2,FALSE())) | K19: Fuerte | L19: 4 | N19: 9e-05 | O19: =IF(I18="","",I18+N19) | P19: =IF(C18=0,"",C18) | Q19: =I18
B20: =I20 | I20: =IF(ISERROR(VLOOKUP(E20,$K$10:$L$14,2,FALSE())*VLOOKUP(G20,$K$18:$L$22,2,FALSE())*VLOOKUP(H20,$K$26:$L$30,2,FALSE())),"",VLOOKUP(E20,$K$10:$L$14,2,FALSE())*VLOOKUP(G20,$K$18:$L$22,2,FALSE())*VLOOKUP(H20,$K$26:$L$30,2,FALSE())) | K20: Promedio | L20: 3 | N20: 8e-05 | O20: =IF(I19="","",I19+N20) | P20: =IF(C19=0,"",C19) | Q20: =I19
B21: =I21 | I21: =IF(ISERROR(VLOOKUP(E21,$K$10:$L$14,2,FALSE())*VLOOKUP(G21,$K$18:$L$22,2,FALSE())*VLOOKUP(H21,$K$26:$L$30,2,FALSE())),"",VLOOKUP(E21,$K$10:$L$14,2,FALSE())*VLOOKUP(G21,$K$18:$L$22,2,FALSE())*VLOOKUP(H21,$K$26:$L$30,2,FALSE())) | K21: Débil | L21: 2 | N21: 7e-05 | O21: =IF(I20="","",I20+N21) | P21: =IF(C20=0,"",C20) | Q21: =I20
B22: =I22 | I22: =IF(ISERROR(VLOOKUP(E22,$K$10:$L$14,2,FALSE())*VLOOKUP(G22,$K$18:$L$22,2,FALSE())*VLOOKUP(H22,$K$26:$L$30,2,FALSE())),"",VLOOKUP(E22,$K$10:$L$14,2,FALSE())*VLOOKUP(G22,$K$18:$L$22,2,FALSE())*VLOOKUP(H22,$K$26:$L$30,2,FALSE())) | K22: Muy Débil | L22: 1 | N22: 6e-05 | O22: =IF(I21="","",I21+N22) | P22: =IF(C21=0,"",C21) | Q22: =I21
B23: =I23 | I23: =IF(ISERROR(VLOOKUP(E23,$K$10:$L$14,2,FALSE())*VLOOKUP(G23,$K$18:$L$22,2,FALSE())*VLOOKUP(H23,$K$26:$L$30,2,FALSE())),"",VLOOKUP(E23,$K$10:$L$14,2,FALSE())*VLOOKUP(G23,$K$18:$L$22,2,FALSE())*VLOOKUP(H23,$K$26:$L$30,2,FALSE())) | N23: 5e-05 | O23: =IF(I22="","",I22+N23) | P23: =IF(C22=0,"",C22) | Q23: =I22
B24: =I24 | I24: =IF(ISERROR(VLOOKUP(E24,$K$10:$L$14,2,FALSE())*VLOOKUP(G24,$K$18:$L$22,2,FALSE())*VLOOKUP(H24,$K$26:$L$30,2,FALSE())),"",VLOOKUP(E24,$K$10:$L$14,2,FALSE())*VLOOKUP(G24,$K$18:$L$22,2,FALSE())*VLOOKUP(H24,$K$26:$L$30,2,FALSE())) | K24: Tendencia | N24: 4e-05 | O24: =IF(I23="","",I23+N24) | P24: =IF(C23=0,"",C23) | Q24: =I23
B25: =I25 | I25: =IF(ISERROR(VLOOKUP(E25,$K$10:$L$14,2,FALSE())*VLOOKUP(G25,$K$18:$L$22,2,FALSE())*VLOOKUP(H25,$K$26:$L$30,2,FALSE())),"",VLOOKUP(E25,$K$10:$L$14,2,FALSE())*VLOOKUP(G25,$K$18:$L$22,2,FALSE())*VLOOKUP(H25,$K$26:$L$30,2,FALSE())) | N25: 3e-05 | O25: =IF(I24="","",I24+N25) | P25: =IF(C24=0,"",C24) | Q25: =I24
B26: =I26 | I26: =IF(ISERROR(VLOOKUP(E26,$K$10:$L$14,2,FALSE())*VLOOKUP(G26,$K$18:$L$22,2,FALSE())*VLOOKUP(H26,$K$26:$L$30,2,FALSE())),"",VLOOKUP(E26,$K$10:$L$14,2,FALSE())*VLOOKUP(G26,$K$18:$L$22,2,FALSE())*VLOOKUP(H26,$K$26:$L$30,2,FALSE())) | K26: Mejora Mucho | L26: 5 | N26: 2e-05 | O26: =IF(I25="","",I25+N26) | P26: =IF(C25=0,"",C25) | Q26: =I25
B27: =I27 | I27: =IF(ISERROR(VLOOKUP(E27,$K$10:$L$14,2,FALSE())*VLOOKUP(G27,$K$18:$L$22,2,FALSE())*VLOOKUP(H27,$K$26:$L$30,2,FALSE())),"",VLOOKUP(E27,$K$10:$L$14,2,FALSE())*VLOOKUP(G27,$K$18:$L$22,2,FALSE())*VLOOKUP(H27,$K$26:$L$30,2,FALSE())) | K27: Mejora | L27: 4 | N27: 1e-05 | O27: =IF(I26="","",I26+N27) | P27: =IF(C26=0,"",C26) | Q27: =I26
B28: =I28 | I28: =IF(ISERROR(VLOOKUP(E28,$K$10:$L$14,2,FALSE())*VLOOKUP(G28,$K$18:$L$22,2,FALSE())*VLOOKUP(H28,$K$26:$L$30,2,FALSE())),"",VLOOKUP(E28,$K$10:$L$14,2,FALSE())*VLOOKUP(G28,$K$18:$L$22,2,FALSE())*VLOOKUP(H28,$K$26:$L$30,2,FALSE())) | K28: Indiferente | L28: 3
B29: =I29 | I29: =IF(ISERROR(VLOOKUP(E29,$K$10:$L$14,2,FALSE())*VLOOKUP(G29,$K$18:$L$22,2,FALSE())*VLOOKUP(H29,$K$26:$L$30,2,FALSE())),"",VLOOKUP(E29,$K$10:$L$14,2,FALSE())*VLOOKUP(G29,$K$18:$L$22,2,FALSE())*VLOOKUP(H29,$K$26:$L$30,2,FALSE())) | K29: Peor | L29: 2
B30: =I30 | I30: =IF(ISERROR(VLOOKUP(E30,$K$10:$L$14,2,FALSE())*VLOOKUP(G30,$K$18:$L$22,2,FALSE())*VLOOKUP(H30,$K$26:$L$30,2,FALSE())),"",VLOOKUP(E30,$K$10:$L$14,2,FALSE())*VLOOKUP(G30,$K$18:$L$22,2,FALSE())*VLOOKUP(H30,$K$26:$L$30,2,FALSE())) | K30: Mucho Peor | L30: 1
C31: La puntuación global de los factores económicos | I31: =SUM(I7:I30) -> 330
K32: Marco temporal | O32: =IF(I31="","",I31+N32) -> 330 | P32: =IF(C31=0,"",C31) -> La puntuación global de los factores económicos | Q32: =I31 -> 330
K34: Definido
K35: Indefinido

Sheet F_Soc
C1: Parches - Plataforma de Eventos y Networking
C3: FACTOR SOCIAL
C6: Aspectos a evaluar en Factores Sociales | D6: ¿Cómo podrán impactar los aspectos listados en cada uno de los factores de la izquierda en su negocio? | E6: Importancia | F6: Marco Temporal | G6: Intensidad | H6: Tipo de Tendencia | I6: Puntuación
B7: =I7 -> 125 | C7: Urbanización y aislamiento social en ciudades | D7: Tendencia de soledad urbana que crea demanda de conexión social y networking | E7: Muy importante | F7: Indefinido | G7: Muy fuerte | H7: Mejora mucho | I7: =IF(ISERROR(VLOOKUP(E7,$K$10:$L$14,2,FALSE())*VLOOKUP(G7,$K$18:$L$22,2,FALSE())*VLOOKUP(H7,$K$26:$L$30,2,FALSE())),"",VLOOKUP(E7,$K$10:$L$14,2,FALSE())*VLOOKUP(G7,$K$18:$L$22,2,FALSE())*VLOOKUP(H7,$K$26:$L$30,2,FALSE())) -> 125
B8: =I8 -> 75 | C8: Cultura de agrupación social (parches informales) | D8: Disposición cultural colombiana a formar "parches" y eventos sociales espontáneos | E8: Muy importante | F8: Indefinido | G8: Muy fuerte | H8: Indiferente | I8: =IF(ISERROR(VLOOKUP(E8,$K$10:$L$14,2,FALSE())*VLOOKUP(G8,$K$18:$L$22,2,FALSE())*VLOOKUP(H8,$K$26:$L$30,2,FALSE())),"",VLOOKUP(E8,$K$10:$L$14,2,FALSE())*VLOOKUP(G8,$K$18:$L$22,2,FALSE())*VLOOKUP(H8,$K$26:$L$30,2,FALSE())) -> 75 | K8: Importancia | N8: 0.0002 | O8: =IF(I7="","",I7+N8) -> 125.0002 | P8: =IF(C7=0,"",C7) -> Urbanización y aislamiento social en ciudades | Q8: =I7 -> 125
B9: =I9 -> 125 | C9: Aceptación de plataformas digitales sociales entre jóvenes | D9: Adopción de apps de dating, redes sociales y networking entre millennials y Gen Z | E9: Muy importante | F9: Indefinido | G9: Muy fuerte | H9: Mejora mucho | I9: =IF(ISERROR(VLOOKUP(E9,$K$10:$L$14,2,FALSE())*VLOOKUP(G9,$K$18:$L$22,2,FALSE())*VLOOKUP(H9,$K$26:$L$30,2,FALSE())),"",VLOOKUP(E9,$K$10:$L$14,2,FALSE())*VLOOKUP(G9,$K$18:$L$22,2,FALSE())*VLOOKUP(H9,$K$26:$L$30,2,FALSE())) -> 125 | N9: 0.00019 | O9: =IF(I8="","",I8+N9) -> 75.00019 | P9: =IF(C8=0,"",C8) -> Cultura de agrupación social (parches informales) | Q9: =I8 -> 75
B10: =I10 -> 100 | C10: Preocupaciones de seguridad en encuentros presenciales | D10: Riesgos percibidos de asistir a eventos con desconocidos, especialmente en mujeres; esta desconfianza se intensifica tras el terremoto de agosto de 2026 por la incertidumbre sobre la seguridad estructural de edificaciones y espacios públicos en las zonas afectadas | E10: Muy importante | F10: Indefinido | G10: Muy fuerte | H10: Mejora | I10: =IF(ISERROR(VLOOKUP(E10,$K$10:$L$14,2,FALSE())*VLOOKUP(G10,$K$18:$L$22,2,FALSE())*VLOOKUP(H10,$K$26:$L$30,2,FALSE())),"",VLOOKUP(E10,$K$10:$L$14,2,FALSE())*VLOOKUP(G10,$K$18:$L$22,2,FALSE())*VLOOKUP(H10,$K$26:$L$30,2,FALSE())) -> 100 | K10: Sin importancia | L10: 1 | N10: 0.00018 | O10: =IF(I9="","",I9+N10) -> 125.00018 | P10: =IF(C9=0,"",C9) -> Aceptación de plataformas digitales sociales entre jóvenes | Q10: =I9 -> 125
B11: =I11 -> 0 | C11: S1 | D11: https://www.portafolio.co/economia/desempleo-en-colombia-durante-febrero-de-2021-550562 | K11: Poco importante | L11: 2 | N11: 0.00017 | O11: =IF(I10="","",I10+N11) -> 100.00017 | P11: =IF(C10=0,"",C10) -> Preocupaciones de seguridad en encuentros presenciales | Q11: =I10 -> 100
B12: =I12 -> 0 | C12: S2 | D12: https://www.mineducacion.gov.co/1759/w3-article-401621.html?_noredirect=1 | K12: Indiferente | L12: 3 | N12: 0.00016 | O12: =IF(I11="","",I11+N12) | P12: =IF(C11=0,"",C11) -> S1 | Q12: =I11 -> 0
B13: =I13 -> 0 | C13: S3 | D13: http://poblacion.population.city/colombia/tulua/#:~:text=Responder%3A%20Tulu%C3%A1%2C%20Colombia%20(unidad,2021%20ser%C3%ADa%3A%20227%20043*. | K13: Importante | L13: 4 | N13: 0.00015 | O13: =IF(I12="","",I12+N13) | P13: =IF(C12=0,"",C12) -> S2 | Q13: =I12 -> 0
B14: =I14 -> 0 | K14: Muy importante | L14: 5 | N14: 0.00014 | O14: =IF(I13="","",I13+N14) | P14: =IF(C13=0,"",C13) -> S3 | Q14: =I13 -> 0
B15: =I15 -> 0 | N15: 0.00013 | O15: =IF(I14="","",I14+N15) | P15: =IF(C14=0,"",C14) | Q15: =I14 -> 0
B16: =I16 -> 0 | K16: Intensidad | N16: 0.00012 | O16: =IF(I15="","",I15+N16) | P16: =IF(C15=0,"",C15) | Q16: =I15 -> 0
B17: =I17 | I17: =IF(ISERROR(VLOOKUP(E17,$K$10:$L$14,2,FALSE())*VLOOKUP(G17,$K$18:$L$22,2,FALSE())*VLOOKUP(H17,$K$26:$L$30,2,FALSE())),"",VLOOKUP(E17,$K$10:$L$14,2,FALSE())*VLOOKUP(G17,$K$18:$L$22,2,FALSE())*VLOOKUP(H17,$K$26:$L$30,2,FALSE())) | N17: 0.00011 | O17: =IF(I16="","",I16+N17) | P17: =IF(C16=0,"",C16) | Q17: =I16 -> 0
B18: =I18 | I18: =IF(ISERROR(VLOOKUP(E18,$K$10:$L$14,2,FALSE())*VLOOKUP(G18,$K$18:$L$22,2,FALSE())*VLOOKUP(H18,$K$26:$L$30,2,FALSE())),"",VLOOKUP(E18,$K$10:$L$14,2,FALSE())*VLOOKUP(G18,$K$18:$L$22,2,FALSE())*VLOOKUP(H18,$K$26:$L$30,2,FALSE())) | K18: Muy Fuerte | L18: 5 | N18: 0.0001 | O18: =IF(I17="","",I17+N18) | P18: =IF(C17=0,"",C17) | Q18: =I17
B19: =I19 | I19: =IF(ISERROR(VLOOKUP(E19,$K$10:$L$14,2,FALSE())*VLOOKUP(G19,$K$18:$L$22,2,FALSE())*VLOOKUP(H19,$K$26:$L$30,2,FALSE())),"",VLOOKUP(E19,$K$10:$L$14,2,FALSE())*VLOOKUP(G19,$K$18:$L$22,2,FALSE())*VLOOKUP(H19,$K$26:$L$30,2,FALSE())) | K19: Fuerte | L19: 4 | N19: 9e-05 | O19: =IF(I18="","",I18+N19) | P19: =IF(C18=0,"",C18) | Q19: =I18
B20: =I20 | I20: =IF(ISERROR(VLOOKUP(E20,$K$10:$L$14,2,FALSE())*VLOOKUP(G20,$K$18:$L$22,2,FALSE())*VLOOKUP(H20,$K$26:$L$30,2,FALSE())),"",VLOOKUP(E20,$K$10:$L$14,2,FALSE())*VLOOKUP(G20,$K$18:$L$22,2,FALSE())*VLOOKUP(H20,$K$26:$L$30,2,FALSE())) | K20: Promedio | L20: 3 | N20: 8e-05 | O20: =IF(I19="","",I19+N20) | P20: =IF(C19=0,"",C19) | Q20: =I19
B21: =I21 | I21: =IF(ISERROR(VLOOKUP(E21,$K$10:$L$14,2,FALSE())*VLOOKUP(G21,$K$18:$L$22,2,FALSE())*VLOOKUP(H21,$K$26:$L$30,2,FALSE())),"",VLOOKUP(E21,$K$10:$L$14,2,FALSE())*VLOOKUP(G21,$K$18:$L$22,2,FALSE())*VLOOKUP(H21,$K$26:$L$30,2,FALSE())) | K21: Débil | L21: 2 | N21: 7e-05 | O21: =IF(I20="","",I20+N21) | P21: =IF(C20=0,"",C20) | Q21: =I20
B22: =I22 | I22: =IF(ISERROR(VLOOKUP(E22,$K$10:$L$14,2,FALSE())*VLOOKUP(G22,$K$18:$L$22,2,FALSE())*VLOOKUP(H22,$K$26:$L$30,2,FALSE())),"",VLOOKUP(E22,$K$10:$L$14,2,FALSE())*VLOOKUP(G22,$K$18:$L$22,2,FALSE())*VLOOKUP(H22,$K$26:$L$30,2,FALSE())) | K22: Muy Débil | L22: 1 | N22: 6e-05 | O22: =IF(I21="","",I21+N22) | P22: =IF(C21=0,"",C21) | Q22: =I21
B23: =I23 | I23: =IF(ISERROR(VLOOKUP(E23,$K$10:$L$14,2,FALSE())*VLOOKUP(G23,$K$18:$L$22,2,FALSE())*VLOOKUP(H23,$K$26:$L$30,2,FALSE())),"",VLOOKUP(E23,$K$10:$L$14,2,FALSE())*VLOOKUP(G23,$K$18:$L$22,2,FALSE())*VLOOKUP(H23,$K$26:$L$30,2,FALSE())) | N23: 5e-05 | O23: =IF(I22="","",I22+N23) | P23: =IF(C22=0,"",C22) | Q23: =I22
B24: =I24 | I24: =IF(ISERROR(VLOOKUP(E24,$K$10:$L$14,2,FALSE())*VLOOKUP(G24,$K$18:$L$22,2,FALSE())*VLOOKUP(H24,$K$26:$L$30,2,FALSE())),"",VLOOKUP(E24,$K$10:$L$14,2,FALSE())*VLOOKUP(G24,$K$18:$L$22,2,FALSE())*VLOOKUP(H24,$K$26:$L$30,2,FALSE())) | K24: Tendencia | N24: 4e-05 | O24: =IF(I23="","",I23+N24) | P24: =IF(C23=0,"",C23) | Q24: =I23
B25: =I25 | I25: =IF(ISERROR(VLOOKUP(E25,$K$10:$L$14,2,FALSE())*VLOOKUP(G25,$K$18:$L$22,2,FALSE())*VLOOKUP(H25,$K$26:$L$30,2,FALSE())),"",VLOOKUP(E25,$K$10:$L$14,2,FALSE())*VLOOKUP(G25,$K$18:$L$22,2,FALSE())*VLOOKUP(H25,$K$26:$L$30,2,FALSE())) | N25: 3e-05 | O25: =IF(I24="","",I24+N25) | P25: =IF(C24=0,"",C24) | Q25: =I24
B26: =I26 | I26: =IF(ISERROR(VLOOKUP(E26,$K$10:$L$14,2,FALSE())*VLOOKUP(G26,$K$18:$L$22,2,FALSE())*VLOOKUP(H26,$K$26:$L$30,2,FALSE())),"",VLOOKUP(E26,$K$10:$L$14,2,FALSE())*VLOOKUP(G26,$K$18:$L$22,2,FALSE())*VLOOKUP(H26,$K$26:$L$30,2,FALSE())) | K26: Mejora Mucho | L26: 5 | N26: 2e-05 | O26: =IF(I25="","",I25+N26) | P26: =IF(C25=0,"",C25) | Q26: =I25
B27: =I27 | I27: =IF(ISERROR(VLOOKUP(E27,$K$10:$L$14,2,FALSE())*VLOOKUP(G27,$K$18:$L$22,2,FALSE())*VLOOKUP(H27,$K$26:$L$30,2,FALSE())),"",VLOOKUP(E27,$K$10:$L$14,2,FALSE())*VLOOKUP(G27,$K$18:$L$22,2,FALSE())*VLOOKUP(H27,$K$26:$L$30,2,FALSE())) | K27: Mejora | L27: 4 | N27: 1e-05 | O27: =IF(I26="","",I26+N27) | P27: =IF(C26=0,"",C26) | Q27: =I26
B28: =I28 | I28: =IF(ISERROR(VLOOKUP(E28,$K$10:$L$14,2,FALSE())*VLOOKUP(G28,$K$18:$L$22,2,FALSE())*VLOOKUP(H28,$K$26:$L$30,2,FALSE())),"",VLOOKUP(E28,$K$10:$L$14,2,FALSE())*VLOOKUP(G28,$K$18:$L$22,2,FALSE())*VLOOKUP(H28,$K$26:$L$30,2,FALSE())) | K28: Indiferente | L28: 3 | O28: =IF(I27="","",I27+N28) | P28: =IF(C27=0,"",C27) | Q28: =I27
B29: =I29 | I29: =IF(ISERROR(VLOOKUP(E29,$K$10:$L$14,2,FALSE())*VLOOKUP(G29,$K$18:$L$22,2,FALSE())*VLOOKUP(H29,$K$26:$L$30,2,FALSE())),"",VLOOKUP(E29,$K$10:$L$14,2,FALSE())*VLOOKUP(G29,$K$18:$L$22,2,FALSE())*VLOOKUP(H29,$K$26:$L$30,2,FALSE())) | K29: Peor | L29: 2 | O29: =IF(I28="","",I28+N29) | P29: =IF(C28=0,"",C28) | Q29: =I28
B30: =I30 | I30: =IF(ISERROR(VLOOKUP(E30,$K$10:$L$14,2,FALSE())*VLOOKUP(G30,$K$18:$L$22,2,FALSE())*VLOOKUP(H30,$K$26:$L$30,2,FALSE())),"",VLOOKUP(E30,$K$10:$L$14,2,FALSE())*VLOOKUP(G30,$K$18:$L$22,2,FALSE())*VLOOKUP(H30,$K$26:$L$30,2,FALSE())) | K30: Mucho Peor | L30: 1 | O30: =IF(I29="","",I29+N30) | P30: =IF(C29=0,"",C29) | Q30: =I29
C31: La puntuación global de los factores sociales | I31: =SUM(I7:I30) -> 425 | O31: =IF(#REF!="","",#REF!+N31) -> #REF! | P31: =IF(#REF!=0,"",#REF!) -> #REF! | Q31: =#REF! -> #REF!
K32: Marco temporal | O32: =IF(I31="","",I31+N32) -> 425 | P32: =IF(C31=0,"",C31) -> La puntuación global de los factores sociales | Q32: =I31 -> 425
K34: Definido
K35: Indefinido

Sheet F_Tec
C1: Parches - Plataforma de Eventos y Networking
C3: FACTOR TECNOLÓGICO
C6: Aspectos a evaluar en Factores Tecnológicos | D6: ¿Cómo podrán impactar los aspectos listados en cada uno de los factores de la izquierda en su negocio? | E6: Importancia | F6: Marco Temporal | G6: Intensidad | H6: Tipo de Tendencia | I6: Puntuación
B7: =I7 -> 125 | C7: Penetración de internet y smartphones en Colombia | D7: Cobertura móvil y acceso a internet necesario para usar la PWA | E7: Muy importante | F7: Definido | G7: Muy fuerte | H7: Mejora mucho | I7: =IF(ISERROR(VLOOKUP(E7,$K$10:$L$14,2,FALSE())*VLOOKUP(G7,$K$18:$L$22,2,FALSE())*VLOOKUP(H7,$K$26:$L$30,2,FALSE())),"",VLOOKUP(E7,$K$10:$L$14,2,FALSE())*VLOOKUP(G7,$K$18:$L$22,2,FALSE())*VLOOKUP(H7,$K$26:$L$30,2,FALSE())) -> 125
B8: =I8 -> 80 | C8: Disponibilidad de APIs de geolocalización y mapas | D8: Acceso a Google Maps, Mapbox u otras APIs para ubicar eventos en tiempo real | E8: Importante | F8: Indefinido | G8: Muy fuerte | H8: Mejora | I8: =IF(ISERROR(VLOOKUP(E8,$K$10:$L$14,2,FALSE())*VLOOKUP(G8,$K$18:$L$22,2,FALSE())*VLOOKUP(H8,$K$26:$L$30,2,FALSE())),"",VLOOKUP(E8,$K$10:$L$14,2,FALSE())*VLOOKUP(G8,$K$18:$L$22,2,FALSE())*VLOOKUP(H8,$K$26:$L$30,2,FALSE())) -> 80 | K8: Importancia | N8: 0.0002 | O8: =IF(I7="","",I7+N8) -> 125.0002 | P8: =IF(C7=0,"",C7) -> Penetración de internet y smartphones en Colombia | Q8: =I7 -> 125
B9: =I9 -> 100 | C9: Madurez de tecnologías biométricas y facial recognition | D9: Disponibilidad de servicios de verificación facial (liveness detection) en Colombia | E9: Muy importante | F9: Definido | G9: Fuerte | H9: Mejora mucho | I9: =IF(ISERROR(VLOOKUP(E9,$K$10:$L$14,2,FALSE())*VLOOKUP(G9,$K$18:$L$22,2,FALSE())*VLOOKUP(H9,$K$26:$L$30,2,FALSE())),"",VLOOKUP(E9,$K$10:$L$14,2,FALSE())*VLOOKUP(G9,$K$18:$L$22,2,FALSE())*VLOOKUP(H9,$K$26:$L$30,2,FALSE())) -> 100 | N9: 0.00019 | O9: =IF(I8="","",I8+N9) -> 80.00019 | P9: =IF(C8=0,"",C8) -> Disponibilidad de APIs de geolocalización y mapas | Q9: =I8 -> 80
B10: =I10 -> 100 | C10: Infraestructura cloud y hosting colombiano | D10: Disponibilidad de servidores confiables locales o regionales para cumplir GDPR y Habeas Data; el terremoto de agosto de 2026 evidenció la fragilidad de la conectividad (cortes masivos de electricidad, telefonía e internet en Chocó, Valle del Cauca, Risaralda, Quindío y Caldas), lo que exige arquitectura redundante y modo offline para la continuidad del servicio | E10: Muy importante | F10: Indefinido | G10: Muy fuerte | H10: Mejora | I10: =IF(ISERROR(VLOOKUP(E10,$K$10:$L$14,2,FALSE())*VLOOKUP(G10,$K$18:$L$22,2,FALSE())*VLOOKUP(H10,$K$26:$L$30,2,FALSE())),"",VLOOKUP(E10,$K$10:$L$14,2,FALSE())*VLOOKUP(G10,$K$18:$L$22,2,FALSE())*VLOOKUP(H10,$K$26:$L$30,2,FALSE())) -> 100 | K10: Sin importancia | L10: 1 | N10: 0.00018 | O10: =IF(I9="","",I9+N10) -> 100.00018 | P10: =IF(C9=0,"",C9) -> Madurez de tecnologías biométricas y facial recognition | Q10: =I9 -> 100
B11: =I11 -> 0 | C11: T1 | D11: https://www.mintic.gov.co/portal/715/w3-article-428676.html | K11: Poco importante | L11: 2 | N11: 0.00017 | O11: =IF(I10="","",I10+N11) -> 100.00017 | P11: =IF(C10=0,"",C10) -> Infraestructura cloud y hosting colombiano | Q11: =I10 -> 100
B12: =I12 -> 0 | C12: T2 | D12: https://www.infobae.com/tecno/2026/08/10/colombia-tiene-fallas-en-telecomunicaciones-tras-el-terremoto-claro-y-tigo-con-telefonia-e-internet/ | K12: Indiferente | L12: 3 | N12: 0.00016 | O12: =IF(I11="","",I11+N12) | P12: =IF(C11=0,"",C11) -> T1 | Q12: =I11 -> 0
B13: =I13 -> 0 | C13: T3 | D13: https://revistacloud.com/colombia-recupera-sus-telecomunicaciones-tras-el-terremoto-el-80-de-la-red-de-claro-vuelve-a-operar | K13: Importante | L13: 4 | N13: 0.00015 | O13: =IF(I12="","",I12+N13) | P13: =IF(C12=0,"",C12) -> T2 | Q13: =I12 -> 0
B14: =I14 -> 0 | K14: Muy importante | L14: 5 | N14: 0.00014 | O14: =IF(I13="","",I13+N14) | P14: =IF(C13=0,"",C13) -> T3 | Q14: =I13 -> 0
B15: =I15 -> 0 | N15: 0.00013 | O15: =IF(I14="","",I14+N15) | P15: =IF(C14=0,"",C14) | Q15: =I14 -> 0
B16: =I16 | I16: =IF(ISERROR(VLOOKUP(E16,$K$10:$L$14,2,FALSE())*VLOOKUP(G16,$K$18:$L$22,2,FALSE())*VLOOKUP(H16,$K$26:$L$30,2,FALSE())),"",VLOOKUP(E16,$K$10:$L$14,2,FALSE())*VLOOKUP(G16,$K$18:$L$22,2,FALSE())*VLOOKUP(H16,$K$26:$L$30,2,FALSE())) | K16: Intensidad | N16: 0.00012 | O16: =IF(I15="","",I15+N16) | P16: =IF(C15=0,"",C15) | Q16: =I15 -> 0
B17: =I17 | I17: =IF(ISERROR(VLOOKUP(E17,$K$10:$L$14,2,FALSE())*VLOOKUP(G17,$K$18:$L$22,2,FALSE())*VLOOKUP(H17,$K$26:$L$30,2,FALSE())),"",VLOOKUP(E17,$K$10:$L$14,2,FALSE())*VLOOKUP(G17,$K$18:$L$22,2,FALSE())*VLOOKUP(H17,$K$26:$L$30,2,FALSE())) | N17: 0.00011 | O17: =IF(I16="","",I16+N17) | P17: =IF(C16=0,"",C16) | Q17: =I16
B18: =I18 | I18: =IF(ISERROR(VLOOKUP(E18,$K$10:$L$14,2,FALSE())*VLOOKUP(G18,$K$18:$L$22,2,FALSE())*VLOOKUP(H18,$K$26:$L$30,2,FALSE())),"",VLOOKUP(E18,$K$10:$L$14,2,FALSE())*VLOOKUP(G18,$K$18:$L$22,2,FALSE())*VLOOKUP(H18,$K$26:$L$30,2,FALSE())) | K18: Muy Fuerte | L18: 5 | N18: 0.0001 | O18: =IF(I17="","",I17+N18) | P18: =IF(C17=0,"",C17) | Q18: =I17
B19: =I19 | I19: =IF(ISERROR(VLOOKUP(E19,$K$10:$L$14,2,FALSE())*VLOOKUP(G19,$K$18:$L$22,2,FALSE())*VLOOKUP(H19,$K$26:$L$30,2,FALSE())),"",VLOOKUP(E19,$K$10:$L$14,2,FALSE())*VLOOKUP(G19,$K$18:$L$22,2,FALSE())*VLOOKUP(H19,$K$26:$L$30,2,FALSE())) | K19: Fuerte | L19: 4 | N19: 9e-05 | O19: =IF(I18="","",I18+N19) | P19: =IF(C18=0,"",C18) | Q19: =I18
B20: =I20 | I20: =IF(ISERROR(VLOOKUP(E20,$K$10:$L$14,2,FALSE())*VLOOKUP(G20,$K$18:$L$22,2,FALSE())*VLOOKUP(H20,$K$26:$L$30,2,FALSE())),"",VLOOKUP(E20,$K$10:$L$14,2,FALSE())*VLOOKUP(G20,$K$18:$L$22,2,FALSE())*VLOOKUP(H20,$K$26:$L$30,2,FALSE())) | K20: Promedio | L20: 3 | N20: 8e-05 | O20: =IF(I19="","",I19+N20) | P20: =IF(C19=0,"",C19) | Q20: =I19
B21: =I21 | I21: =IF(ISERROR(VLOOKUP(E21,$K$10:$L$14,2,FALSE())*VLOOKUP(G21,$K$18:$L$22,2,FALSE())*VLOOKUP(H21,$K$26:$L$30,2,FALSE())),"",VLOOKUP(E21,$K$10:$L$14,2,FALSE())*VLOOKUP(G21,$K$18:$L$22,2,FALSE())*VLOOKUP(H21,$K$26:$L$30,2,FALSE())) | K21: Débil | L21: 2 | N21: 7e-05 | O21: =IF(I20="","",I20+N21) | P21: =IF(C20=0,"",C20) | Q21: =I20
B22: =I22 | I22: =IF(ISERROR(VLOOKUP(E22,$K$10:$L$14,2,FALSE())*VLOOKUP(G22,$K$18:$L$22,2,FALSE())*VLOOKUP(H22,$K$26:$L$30,2,FALSE())),"",VLOOKUP(E22,$K$10:$L$14,2,FALSE())*VLOOKUP(G22,$K$18:$L$22,2,FALSE())*VLOOKUP(H22,$K$26:$L$30,2,FALSE())) | K22: Muy Débil | L22: 1 | N22: 6e-05 | O22: =IF(I21="","",I21+N22) | P22: =IF(C21=0,"",C21) | Q22: =I21
B23: =I23 | I23: =IF(ISERROR(VLOOKUP(E23,$K$10:$L$14,2,FALSE())*VLOOKUP(G23,$K$18:$L$22,2,FALSE())*VLOOKUP(H23,$K$26:$L$30,2,FALSE())),"",VLOOKUP(E23,$K$10:$L$14,2,FALSE())*VLOOKUP(G23,$K$18:$L$22,2,FALSE())*VLOOKUP(H23,$K$26:$L$30,2,FALSE())) | N23: 5e-05 | O23: =IF(I22="","",I22+N23) | P23: =IF(C22=0,"",C22) | Q23: =I22
B24: =I24 | I24: =IF(ISERROR(VLOOKUP(E24,$K$10:$L$14,2,FALSE())*VLOOKUP(G24,$K$18:$L$22,2,FALSE())*VLOOKUP(H24,$K$26:$L$30,2,FALSE())),"",VLOOKUP(E24,$K$10:$L$14,2,FALSE())*VLOOKUP(G24,$K$18:$L$22,2,FALSE())*VLOOKUP(H24,$K$26:$L$30,2,FALSE())) | K24: Tendencia | N24: 4e-05 | O24: =IF(I23="","",I23+N24) | P24: =IF(C23=0,"",C23) | Q24: =I23
B25: =I25 | I25: =IF(ISERROR(VLOOKUP(E25,$K$10:$L$14,2,FALSE())*VLOOKUP(G25,$K$18:$L$22,2,FALSE())*VLOOKUP(H25,$K$26:$L$30,2,FALSE())),"",VLOOKUP(E25,$K$10:$L$14,2,FALSE())*VLOOKUP(G25,$K$18:$L$22,2,FALSE())*VLOOKUP(H25,$K$26:$L$30,2,FALSE())) | N25: 3e-05 | O25: =IF(I24="","",I24+N25) | P25: =IF(C24=0,"",C24) | Q25: =I24
B26: =I26 | I26: =IF(ISERROR(VLOOKUP(E26,$K$10:$L$14,2,FALSE())*VLOOKUP(G26,$K$18:$L$22,2,FALSE())*VLOOKUP(H26,$K$26:$L$30,2,FALSE())),"",VLOOKUP(E26,$K$10:$L$14,2,FALSE())*VLOOKUP(G26,$K$18:$L$22,2,FALSE())*VLOOKUP(H26,$K$26:$L$30,2,FALSE())) | K26: Mejora Mucho | L26: 5 | N26: 2e-05 | O26: =IF(I25="","",I25+N26) | P26: =IF(C25=0,"",C25) | Q26: =I25
B27: =I27 | I27: =IF(ISERROR(VLOOKUP(E27,$K$10:$L$14,2,FALSE())*VLOOKUP(G27,$K$18:$L$22,2,FALSE())*VLOOKUP(H27,$K$26:$L$30,2,FALSE())),"",VLOOKUP(E27,$K$10:$L$14,2,FALSE())*VLOOKUP(G27,$K$18:$L$22,2,FALSE())*VLOOKUP(H27,$K$26:$L$30,2,FALSE())) | K27: Mejora | L27: 4 | N27: 1e-05 | O27: =IF(I26="","",I26+N27) | P27: =IF(C26=0,"",C26) | Q27: =I26
B28: =I28 | I28: =IF(ISERROR(VLOOKUP(E28,$K$10:$L$14,2,FALSE())*VLOOKUP(G28,$K$18:$L$22,2,FALSE())*VLOOKUP(H28,$K$26:$L$30,2,FALSE())),"",VLOOKUP(E28,$K$10:$L$14,2,FALSE())*VLOOKUP(G28,$K$18:$L$22,2,FALSE())*VLOOKUP(H28,$K$26:$L$30,2,FALSE())) | K28: Indiferente | L28: 3
B29: =I29 | I29: =IF(ISERROR(VLOOKUP(E29,$K$10:$L$14,2,FALSE())*VLOOKUP(G29,$K$18:$L$22,2,FALSE())*VLOOKUP(H29,$K$26:$L$30,2,FALSE())),"",VLOOKUP(E29,$K$10:$L$14,2,FALSE())*VLOOKUP(G29,$K$18:$L$22,2,FALSE())*VLOOKUP(H29,$K$26:$L$30,2,FALSE())) | K29: Peor | L29: 2
B30: =I30 | I30: =IF(ISERROR(VLOOKUP(E30,$K$10:$L$14,2,FALSE())*VLOOKUP(G30,$K$18:$L$22,2,FALSE())*VLOOKUP(H30,$K$26:$L$30,2,FALSE())),"",VLOOKUP(E30,$K$10:$L$14,2,FALSE())*VLOOKUP(G30,$K$18:$L$22,2,FALSE())*VLOOKUP(H30,$K$26:$L$30,2,FALSE())) | K30: Mucho Peor | L30: 1
C31: La puntuación global de los factores tecnológicos | I31: =SUM(I7:I30) -> 405
K32: Marco temporal | O32: =IF(I31="","",I31+N32) -> 405 | P32: =IF(C31=0,"",C31) -> La puntuación global de los factores tecnológicos | Q32: =I31 -> 405
K34: Definido
K35: Indefinido

Sheet F_Amb
C1: Parches - Plataforma de Eventos y Networking
C3: FACTOR AMBIENTAL
C6: Aspectos a evaluar Factores Ambientales | D6: ¿Cómo podrán impactar los aspectos listados en cada uno de los factores de la izquierda en su negocio? | E6: Importancia | F6: Marco Temporal | G6: Intensidad | H6: Tipo de Tendencia | I6: Puntuación
B7: =I7 -> 16 | C7: Sostenibilidad de eventos y movilidad urbana | D7: Impacto ambiental de incentivar desplazamientos urbanos para asistir a eventos | E7: Poco importante | F7: Indefinido | G7: Débil | H7: Mejora | I7: =IF(ISERROR(VLOOKUP(E7,$K$10:$L$14,2,FALSE())*VLOOKUP(G7,$K$18:$L$22,2,FALSE())*VLOOKUP(H7,$K$26:$L$30,2,FALSE())),"",VLOOKUP(E7,$K$10:$L$14,2,FALSE())*VLOOKUP(G7,$K$18:$L$22,2,FALSE())*VLOOKUP(H7,$K$26:$L$30,2,FALSE())) -> 16
B8: =I8 -> 16 | C8: Carbono digital y consumo energético de servidores | D8: Huella de carbono de la plataforma en hosting y procesamiento de datos | E8: Poco importante | F8: Definido | G8: Débil | H8: Mejora | I8: =IF(ISERROR(VLOOKUP(E8,$K$10:$L$14,2,FALSE())*VLOOKUP(G8,$K$18:$L$22,2,FALSE())*VLOOKUP(H8,$K$26:$L$30,2,FALSE())),"",VLOOKUP(E8,$K$10:$L$14,2,FALSE())*VLOOKUP(G8,$K$18:$L$22,2,FALSE())*VLOOKUP(H8,$K$26:$L$30,2,FALSE())) -> 16 | K8: Importancia | N8: 0.0002 | O8: =IF(I7="","",I7+N8) -> 16.0002 | P8: =IF(C7=0,"",C7) -> Sostenibilidad de eventos y movilidad urbana | Q8: =I7 -> 16
B9: =I9 -> 50 | C9: Amenazas por medio de la pandemia COVID 19 en el ambiente | D9: Los cierres, aforos limitados y cancelaciones de eventos presenciales derivados de emergencias sanitarias como el COVID-19 afectan directamente la operación de una plataforma centrada en encuentros presenciales, obligando a prever protocolos de bioseguridad y flexibilidad ante restricciones de aforo | E9: Muy importante | F9: Indefinido | G9: Muy Fuerte | H9: Peor | I9: =IF(ISERROR(VLOOKUP(E9,$K$10:$L$14,2,FALSE())*VLOOKUP(G9,$K$18:$L$22,2,FALSE())*VLOOKUP(H9,$K$26:$L$30,2,FALSE())),"",VLOOKUP(E9,$K$10:$L$14,2,FALSE())*VLOOKUP(G9,$K$18:$L$22,2,FALSE())*VLOOKUP(H9,$K$26:$L$30,2,FALSE())) -> 50 | N9: 0.00019 | O9: =IF(I8="","",I8+N9) -> 16.00019 | P9: =IF(C8=0,"",C8) -> Carbono digital y consumo energético de servidores | Q9: =I8 -> 16
B10: =I10 -> 50 | C10: Riesgo sísmico y desastres naturales en Colombia | D10: El terremoto de magnitud 7,4 del 10 de agosto de 2026 en Chocó (más de 176 muertos, desastre nacional declarado, daños estimados entre $20 y $40 billones) confirma que Colombia opera en zona de alto riesgo sísmico; obliga a evaluar la seguridad estructural de los recintos aliados e incorporar cláusulas de fuerza mayor y seguros para eventos presenciales | E10: Muy importante | F10: Indefinido | G10: Muy Fuerte | H10: Peor | I10: =IF(ISERROR(VLOOKUP(E10,$K$10:$L$14,2,FALSE())*VLOOKUP(G10,$K$18:$L$22,2,FALSE())*VLOOKUP(H10,$K$26:$L$30,2,FALSE())),"",VLOOKUP(E10,$K$10:$L$14,2,FALSE())*VLOOKUP(G10,$K$18:$L$22,2,FALSE())*VLOOKUP(H10,$K$26:$L$30,2,FALSE())) -> 50 | K10: Sin importancia | L10: 1 | N10: 0.00018 | O10: =IF(I9="","",I9+N10) -> 50.00018 | P10: =IF(C9=0,"",C9) -> Amenazas por medio de la pandemia COVID 19 en el ambiente | Q10: =I9 -> 50
B11: =I11 -> 0 | C11: EC1 | D11: https://amenazasismica.sgc.gov.co/ | K11: Poco importante | L11: 2 | N11: 0.00017 | O11: =IF(I10="","",I10+N11) -> 50.00017 | P11: =IF(C10=0,"",C10) -> Riesgo sísmico y desastres naturales en Colombia | Q11: =I10 -> 50
B12: =I12 -> 0 | C12: EC2 | D12: https://www.idiger.gov.co/escenarios-de-riesgo/sismico/en-colombia | K12: Indiferente | L12: 3 | N12: 0.00016 | O12: =IF(I11="","",I11+N12) | P12: =IF(C11=0,"",C11) -> EC1 | Q12: =I11 -> 0
B13: =I13 | C13: EC3 | D13: https://www.paho.org/es/documentos/informe-situacion-1-colombia-terremoto-agosto-2026-10-agosto-2026 | I13: =IF(ISERROR(VLOOKUP(E13,$K$10:$L$14,2,FALSE())*VLOOKUP(G13,$K$18:$L$22,2,FALSE())*VLOOKUP(H13,$K$26:$L$30,2,FALSE())),"",VLOOKUP(E13,$K$10:$L$14,2,FALSE())*VLOOKUP(G13,$K$18:$L$22,2,FALSE())*VLOOKUP(H13,$K$26:$L$30,2,FALSE())) | K13: Importante | L13: 4 | N13: 0.00015 | O13: =IF(I12="","",I12+N13) | P13: =IF(C12=0,"",C12) -> EC2 | Q13: =I12 -> 0
B14: =I14 | I14: =IF(ISERROR(VLOOKUP(E14,$K$10:$L$14,2,FALSE())*VLOOKUP(G14,$K$18:$L$22,2,FALSE())*VLOOKUP(H14,$K$26:$L$30,2,FALSE())),"",VLOOKUP(E14,$K$10:$L$14,2,FALSE())*VLOOKUP(G14,$K$18:$L$22,2,FALSE())*VLOOKUP(H14,$K$26:$L$30,2,FALSE())) | K14: Muy importante | L14: 5 | N14: 0.00014 | O14: =IF(I13="","",I13+N14) | P14: =IF(C13=0,"",C13) -> EC3 | Q14: =I13
B15: =I15 | I15: =IF(ISERROR(VLOOKUP(E15,$K$10:$L$14,2,FALSE())*VLOOKUP(G15,$K$18:$L$22,2,FALSE())*VLOOKUP(H15,$K$26:$L$30,2,FALSE())),"",VLOOKUP(E15,$K$10:$L$14,2,FALSE())*VLOOKUP(G15,$K$18:$L$22,2,FALSE())*VLOOKUP(H15,$K$26:$L$30,2,FALSE())) | N15: 0.00013 | O15: =IF(I14="","",I14+N15) | P15: =IF(C14=0,"",C14) | Q15: =I14
B16: =I16 | I16: =IF(ISERROR(VLOOKUP(E16,$K$10:$L$14,2,FALSE())*VLOOKUP(G16,$K$18:$L$22,2,FALSE())*VLOOKUP(H16,$K$26:$L$30,2,FALSE())),"",VLOOKUP(E16,$K$10:$L$14,2,FALSE())*VLOOKUP(G16,$K$18:$L$22,2,FALSE())*VLOOKUP(H16,$K$26:$L$30,2,FALSE())) | K16: Intensidad | N16: 0.00012 | O16: =IF(I15="","",I15+N16) | P16: =IF(C15=0,"",C15) | Q16: =I15
B17: =I17 | I17: =IF(ISERROR(VLOOKUP(E17,$K$10:$L$14,2,FALSE())*VLOOKUP(G17,$K$18:$L$22,2,FALSE())*VLOOKUP(H17,$K$26:$L$30,2,FALSE())),"",VLOOKUP(E17,$K$10:$L$14,2,FALSE())*VLOOKUP(G17,$K$18:$L$22,2,FALSE())*VLOOKUP(H17,$K$26:$L$30,2,FALSE())) | N17: 0.00011 | O17: =IF(I16="","",I16+N17) | P17: =IF(C16=0,"",C16) | Q17: =I16
B18: =I18 | I18: =IF(ISERROR(VLOOKUP(E18,$K$10:$L$14,2,FALSE())*VLOOKUP(G18,$K$18:$L$22,2,FALSE())*VLOOKUP(H18,$K$26:$L$30,2,FALSE())),"",VLOOKUP(E18,$K$10:$L$14,2,FALSE())*VLOOKUP(G18,$K$18:$L$22,2,FALSE())*VLOOKUP(H18,$K$26:$L$30,2,FALSE())) | K18: Muy Fuerte | L18: 5 | N18: 0.0001 | O18: =IF(I17="","",I17+N18) | P18: =IF(C17=0,"",C17) | Q18: =I17
B19: =I19 | I19: =IF(ISERROR(VLOOKUP(E19,$K$10:$L$14,2,FALSE())*VLOOKUP(G19,$K$18:$L$22,2,FALSE())*VLOOKUP(H19,$K$26:$L$30,2,FALSE())),"",VLOOKUP(E19,$K$10:$L$14,2,FALSE())*VLOOKUP(G19,$K$18:$L$22,2,FALSE())*VLOOKUP(H19,$K$26:$L$30,2,FALSE())) | K19: Fuerte | L19: 4 | N19: 9e-05 | O19: =IF(I18="","",I18+N19) | P19: =IF(C18=0,"",C18) | Q19: =I18
B20: =I20 | I20: =IF(ISERROR(VLOOKUP(E20,$K$10:$L$14,2,FALSE())*VLOOKUP(G20,$K$18:$L$22,2,FALSE())*VLOOKUP(H20,$K$26:$L$30,2,FALSE())),"",VLOOKUP(E20,$K$10:$L$14,2,FALSE())*VLOOKUP(G20,$K$18:$L$22,2,FALSE())*VLOOKUP(H20,$K$26:$L$30,2,FALSE())) | K20: Promedio | L20: 3 | N20: 8e-05 | O20: =IF(I19="","",I19+N20) | P20: =IF(C19=0,"",C19) | Q20: =I19
B21: =I21 | I21: =IF(ISERROR(VLOOKUP(E21,$K$10:$L$14,2,FALSE())*VLOOKUP(G21,$K$18:$L$22,2,FALSE())*VLOOKUP(H21,$K$26:$L$30,2,FALSE())),"",VLOOKUP(E21,$K$10:$L$14,2,FALSE())*VLOOKUP(G21,$K$18:$L$22,2,FALSE())*VLOOKUP(H21,$K$26:$L$30,2,FALSE())) | K21: Débil | L21: 2 | N21: 7e-05 | O21: =IF(I20="","",I20+N21) | P21: =IF(C20=0,"",C20) | Q21: =I20
B22: =I22 | I22: =IF(ISERROR(VLOOKUP(E22,$K$10:$L$14,2,FALSE())*VLOOKUP(G22,$K$18:$L$22,2,FALSE())*VLOOKUP(H22,$K$26:$L$30,2,FALSE())),"",VLOOKUP(E22,$K$10:$L$14,2,FALSE())*VLOOKUP(G22,$K$18:$L$22,2,FALSE())*VLOOKUP(H22,$K$26:$L$30,2,FALSE())) | K22: Muy Débil | L22: 1 | N22: 6e-05 | O22: =IF(I21="","",I21+N22) | P22: =IF(C21=0,"",C21) | Q22: =I21
B23: =I23 | I23: =IF(ISERROR(VLOOKUP(E23,$K$10:$L$14,2,FALSE())*VLOOKUP(G23,$K$18:$L$22,2,FALSE())*VLOOKUP(H23,$K$26:$L$30,2,FALSE())),"",VLOOKUP(E23,$K$10:$L$14,2,FALSE())*VLOOKUP(G23,$K$18:$L$22,2,FALSE())*VLOOKUP(H23,$K$26:$L$30,2,FALSE())) | N23: 5e-05 | O23: =IF(I22="","",I22+N23) | P23: =IF(C22=0,"",C22) | Q23: =I22
B24: =I24 | I24: =IF(ISERROR(VLOOKUP(E24,$K$10:$L$14,2,FALSE())*VLOOKUP(G24,$K$18:$L$22,2,FALSE())*VLOOKUP(H24,$K$26:$L$30,2,FALSE())),"",VLOOKUP(E24,$K$10:$L$14,2,FALSE())*VLOOKUP(G24,$K$18:$L$22,2,FALSE())*VLOOKUP(H24,$K$26:$L$30,2,FALSE())) | K24: Tendencia | N24: 4e-05 | O24: =IF(I23="","",I23+N24) | P24: =IF(C23=0,"",C23) | Q24: =I23
B25: =I25 | I25: =IF(ISERROR(VLOOKUP(E25,$K$10:$L$14,2,FALSE())*VLOOKUP(G25,$K$18:$L$22,2,FALSE())*VLOOKUP(H25,$K$26:$L$30,2,FALSE())),"",VLOOKUP(E25,$K$10:$L$14,2,FALSE())*VLOOKUP(G25,$K$18:$L$22,2,FALSE())*VLOOKUP(H25,$K$26:$L$30,2,FALSE())) | N25: 3e-05 | O25: =IF(I24="","",I24+N25) | P25: =IF(C24=0,"",C24) | Q25: =I24
B26: =I26 | I26: =IF(ISERROR(VLOOKUP(E26,$K$10:$L$14,2,FALSE())*VLOOKUP(G26,$K$18:$L$22,2,FALSE())*VLOOKUP(H26,$K$26:$L$30,2,FALSE())),"",VLOOKUP(E26,$K$10:$L$14,2,FALSE())*VLOOKUP(G26,$K$18:$L$22,2,FALSE())*VLOOKUP(H26,$K$26:$L$30,2,FALSE())) | K26: Mejora Mucho | L26: 5 | N26: 2e-05 | O26: =IF(I25="","",I25+N26) | P26: =IF(C25=0,"",C25) | Q26: =I25
B27: =I27 | I27: =IF(ISERROR(VLOOKUP(E27,$K$10:$L$14,2,FALSE())*VLOOKUP(G27,$K$18:$L$22,2,FALSE())*VLOOKUP(H27,$K$26:$L$30,2,FALSE())),"",VLOOKUP(E27,$K$10:$L$14,2,FALSE())*VLOOKUP(G27,$K$18:$L$22,2,FALSE())*VLOOKUP(H27,$K$26:$L$30,2,FALSE())) | K27: Mejora | L27: 4 | N27: 1e-05 | O27: =IF(I26="","",I26+N27) | P27: =IF(C26=0,"",C26) | Q27: =I26
B28: =I28 | I28: =IF(ISERROR(VLOOKUP(E28,$K$10:$L$14,2,FALSE())*VLOOKUP(G28,$K$18:$L$22,2,FALSE())*VLOOKUP(H28,$K$26:$L$30,2,FALSE())),"",VLOOKUP(E28,$K$10:$L$14,2,FALSE())*VLOOKUP(G28,$K$18:$L$22,2,FALSE())*VLOOKUP(H28,$K$26:$L$30,2,FALSE())) | K28: Indiferente | L28: 3 | N28: 1e-05 | O28: =IF(I27="","",I27+N28) | P28: =IF(C27=0,"",C27) | Q28: =I27
B29: =I29 | I29: =IF(ISERROR(VLOOKUP(E29,$K$10:$L$14,2,FALSE())*VLOOKUP(G29,$K$18:$L$22,2,FALSE())*VLOOKUP(H29,$K$26:$L$30,2,FALSE())),"",VLOOKUP(E29,$K$10:$L$14,2,FALSE())*VLOOKUP(G29,$K$18:$L$22,2,FALSE())*VLOOKUP(H29,$K$26:$L$30,2,FALSE())) | K29: Peor | L29: 2 | P29: =IF(C28=0,"",C28) | Q29: =I28
B30: =I30 | I30: =IF(ISERROR(VLOOKUP(E30,$K$10:$L$14,2,FALSE())*VLOOKUP(G30,$K$18:$L$22,2,FALSE())*VLOOKUP(H30,$K$26:$L$30,2,FALSE())),"",VLOOKUP(E30,$K$10:$L$14,2,FALSE())*VLOOKUP(G30,$K$18:$L$22,2,FALSE())*VLOOKUP(H30,$K$26:$L$30,2,FALSE())) | K30: Mucho Peor | L30: 1 | P30: =IF(C29=0,"",C29) | Q30: =I29
C31: La puntuación global de los factores ambientales | I31: =SUM(I7:I30) -> 132 | O31: =IF(#REF!="","",#REF!+N31) -> #REF! | P31: =IF(#REF!=0,"",#REF!) -> #REF! | Q31: =#REF! -> #REF!
K32: Marco temporal | O32: =IF(I31="","",I31+N32) -> 132 | P32: =IF(C31=0,"",C31) -> La puntuación global de los factores ambientales | Q32: =I31 -> 132
K34: Definido
K35: Indefinido

Sheet F_Leg
C1: Parches - Plataforma de Eventos y Networking
C3: FACTOR LEGAL
C6: Aspectos a evaluar Factores Legales | D6: ¿Cómo podrán impactar los aspectos listados en cada uno de los factores de la izquierda en su negocio? | E6: Importancia | F6: Marco Temporal | G6: Intensidad | H6: Tipo de Tendencia | I6: Puntuación
B7: =I7 -> 100 | C7: Ley Habeas Data y protección de datos biométricos | D7: Cumplimiento normativo para almacenar fotos, cédulas y datos biométricos de usuarios | E7: Muy importante | F7: Definido | G7: Muy fuerte | H7: Mejora | I7: =IF(ISERROR(VLOOKUP(E7,$K$10:$L$14,2,FALSE())*VLOOKUP(G7,$K$18:$L$22,2,FALSE())*VLOOKUP(H7,$K$26:$L$30,2,FALSE())),"",VLOOKUP(E7,$K$10:$L$14,2,FALSE())*VLOOKUP(G7,$K$18:$L$22,2,FALSE())*VLOOKUP(H7,$K$26:$L$30,2,FALSE())) -> 100
B8: =I8 -> 75 | C8: Responsabilidad civil por encuentros presenciales | D8: Marco legal para incidentes, robos o conflictos derivados de eventos organizados en la plataforma, que ahora también debe contemplar la responsabilidad civil ante daños estructurales o cancelaciones forzadas por desastres naturales como el terremoto de agosto de 2026 | E8: Muy importante | F8: Indefinido | G8: Muy fuerte | H8: Indiferente | I8: =IF(ISERROR(VLOOKUP(E8,$K$10:$L$14,2,FALSE())*VLOOKUP(G8,$K$18:$L$22,2,FALSE())*VLOOKUP(H8,$K$26:$L$30,2,FALSE())),"",VLOOKUP(E8,$K$10:$L$14,2,FALSE())*VLOOKUP(G8,$K$18:$L$22,2,FALSE())*VLOOKUP(H8,$K$26:$L$30,2,FALSE())) -> 75 | K8: Importancia | N8: 0.0002 | O8: =IF(I7="","",I7+N8) -> 100.0002 | P8: =IF(C7=0,"",C7) -> Ley Habeas Data y protección de datos biométricos | Q8: =I7 -> 100
B9: =I9 -> 64 | C9: Regulación de transacciones y boletería digital | D9: Normas sobre devoluciones, cancelaciones y protección del consumidor en venta de entradas (Ley 1480 de 2011); la SIC ya ha sancionado a plataformas de boletería por no reembolsar eventos cancelados, un antecedente clave ante cancelaciones masivas por desastres naturales declarados | E9: Importante | F9: Indefinido | G9: Fuerte | H9: Mejora | I9: =IF(ISERROR(VLOOKUP(E9,$K$10:$L$14,2,FALSE())*VLOOKUP(G9,$K$18:$L$22,2,FALSE())*VLOOKUP(H9,$K$26:$L$30,2,FALSE())),"",VLOOKUP(E9,$K$10:$L$14,2,FALSE())*VLOOKUP(G9,$K$18:$L$22,2,FALSE())*VLOOKUP(H9,$K$26:$L$30,2,FALSE())) -> 64 | N9: 0.00019 | O9: =IF(I8="","",I8+N9) -> 75.00019 | P9: =IF(C8=0,"",C8) -> Responsabilidad civil por encuentros presenciales | Q9: =I8 -> 75
B10: =I10 -> 100 | C10: Verificación de identidad y documentos (Cédula de Ciudadanía) | D10: Legalidad de usar y procesar documento de identidad para validación de usuarios | E10: Muy importante | F10: Indefinido | G10: Muy fuerte | H10: Mejora | I10: =IF(ISERROR(VLOOKUP(E10,$K$10:$L$14,2,FALSE())*VLOOKUP(G10,$K$18:$L$22,2,FALSE())*VLOOKUP(H10,$K$26:$L$30,2,FALSE())),"",VLOOKUP(E10,$K$10:$L$14,2,FALSE())*VLOOKUP(G10,$K$18:$L$22,2,FALSE())*VLOOKUP(H10,$K$26:$L$30,2,FALSE())) -> 100 | K10: Sin importancia | L10: 1 | N10: 0.00018 | O10: =IF(I9="","",I9+N10) -> 64.00018 | P10: =IF(C9=0,"",C9) -> Regulación de transacciones y boletería digital | Q10: =I9 -> 64
B11: =I11 -> 0 | C11: L1 | D11: https://www.funcionpublica.gov.co/eva/gestornormativo/norma.php?i=49981 | K11: Poco importante | L11: 2 | N11: 0.00017 | O11: =IF(I10="","",I10+N11) -> 100.00017 | P11: =IF(C10=0,"",C10) -> Verificación de identidad y documentos (Cédula de Ciudadanía) | Q11: =I10 -> 100
B12: =I12 -> 0 | C12: L2 | D12: https://www.funcionpublica.gov.co/eva/gestornormativo/norma.php?i=44306 | K12: Indiferente | L12: 3 | N12: 0.00016 | O12: =IF(I11="","",I11+N12) | P12: =IF(C11=0,"",C11) -> L1 | Q12: =I11 -> 0
B13: =I13 -> 0 | C13: L3 | D13: https://www.sic.gov.co/superindustria-ordena-a-tuticket-reintegrar-inmediatamente-el-dinero-a-los-consumidores-que-adquirieron-boleteria-para-17-espectaculos-que-fueron-cancelados | K13: Importante | L13: 4 | N13: 0.00015 | O13: =IF(I12="","",I12+N13) | P13: =IF(C12=0,"",C12) -> L2 | Q13: =I12 -> 0
B14: =I14 -> 0 | K14: Muy importante | L14: 5 | N14: 0.00014 | O14: =IF(I13="","",I13+N14) | P14: =IF(C13=0,"",C13) -> L3 | Q14: =I13 -> 0
B15: =I15 -> 0 | N15: 0.00013 | O15: =IF(I14="","",I14+N15) | P15: =IF(C14=0,"",C14) | Q15: =I14 -> 0
B16: =I16 -> 0 | K16: Intensidad | N16: 0.00012 | O16: =IF(I15="","",I15+N16) | P16: =IF(C15=0,"",C15) | Q16: =I15 -> 0
B17: =I17 -> 0 | N17: 0.00011 | O17: =IF(I16="","",I16+N17) | P17: =IF(C16=0,"",C16) | Q17: =I16 -> 0
B18: =I18 | I18: =IF(ISERROR(VLOOKUP(E18,$K$10:$L$14,2,FALSE())*VLOOKUP(G18,$K$18:$L$22,2,FALSE())*VLOOKUP(H18,$K$26:$L$30,2,FALSE())),"",VLOOKUP(E18,$K$10:$L$14,2,FALSE())*VLOOKUP(G18,$K$18:$L$22,2,FALSE())*VLOOKUP(H18,$K$26:$L$30,2,FALSE())) | K18: Muy Fuerte | L18: 5 | N18: 0.0001 | O18: =IF(I17="","",I17+N18) | P18: =IF(C17=0,"",C17) | Q18: =I17 -> 0
B19: =I19 | I19: =IF(ISERROR(VLOOKUP(E19,$K$10:$L$14,2,FALSE())*VLOOKUP(G19,$K$18:$L$22,2,FALSE())*VLOOKUP(H19,$K$26:$L$30,2,FALSE())),"",VLOOKUP(E19,$K$10:$L$14,2,FALSE())*VLOOKUP(G19,$K$18:$L$22,2,FALSE())*VLOOKUP(H19,$K$26:$L$30,2,FALSE())) | K19: Fuerte | L19: 4 | N19: 9e-05 | O19: =IF(I18="","",I18+N19) | P19: =IF(C18=0,"",C18) | Q19: =I18
B20: =I20 | I20: =IF(ISERROR(VLOOKUP(E20,$K$10:$L$14,2,FALSE())*VLOOKUP(G20,$K$18:$L$22,2,FALSE())*VLOOKUP(H20,$K$26:$L$30,2,FALSE())),"",VLOOKUP(E20,$K$10:$L$14,2,FALSE())*VLOOKUP(G20,$K$18:$L$22,2,FALSE())*VLOOKUP(H20,$K$26:$L$30,2,FALSE())) | K20: Promedio | L20: 3 | N20: 8e-05 | O20: =IF(I19="","",I19+N20) | P20: =IF(C19=0,"",C19) | Q20: =I19
B21: =I21 | I21: =IF(ISERROR(VLOOKUP(E21,$K$10:$L$14,2,FALSE())*VLOOKUP(G21,$K$18:$L$22,2,FALSE())*VLOOKUP(H21,$K$26:$L$30,2,FALSE())),"",VLOOKUP(E21,$K$10:$L$14,2,FALSE())*VLOOKUP(G21,$K$18:$L$22,2,FALSE())*VLOOKUP(H21,$K$26:$L$30,2,FALSE())) | K21: Débil | L21: 2 | N21: 7e-05 | O21: =IF(I20="","",I20+N21) | P21: =IF(C20=0,"",C20) | Q21: =I20
B22: =I22 | I22: =IF(ISERROR(VLOOKUP(E22,$K$10:$L$14,2,FALSE())*VLOOKUP(G22,$K$18:$L$22,2,FALSE())*VLOOKUP(H22,$K$26:$L$30,2,FALSE())),"",VLOOKUP(E22,$K$10:$L$14,2,FALSE())*VLOOKUP(G22,$K$18:$L$22,2,FALSE())*VLOOKUP(H22,$K$26:$L$30,2,FALSE())) | K22: Muy Débil | L22: 1 | N22: 6e-05 | O22: =IF(I21="","",I21+N22) | P22: =IF(C21=0,"",C21) | Q22: =I21
B23: =I23 | I23: =IF(ISERROR(VLOOKUP(E23,$K$10:$L$14,2,FALSE())*VLOOKUP(G23,$K$18:$L$22,2,FALSE())*VLOOKUP(H23,$K$26:$L$30,2,FALSE())),"",VLOOKUP(E23,$K$10:$L$14,2,FALSE())*VLOOKUP(G23,$K$18:$L$22,2,FALSE())*VLOOKUP(H23,$K$26:$L$30,2,FALSE())) | N23: 5e-05 | O23: =IF(I22="","",I22+N23) | P23: =IF(C22=0,"",C22) | Q23: =I22
B24: =I24 | I24: =IF(ISERROR(VLOOKUP(E24,$K$10:$L$14,2,FALSE())*VLOOKUP(G24,$K$18:$L$22,2,FALSE())*VLOOKUP(H24,$K$26:$L$30,2,FALSE())),"",VLOOKUP(E24,$K$10:$L$14,2,FALSE())*VLOOKUP(G24,$K$18:$L$22,2,FALSE())*VLOOKUP(H24,$K$26:$L$30,2,FALSE())) | K24: Tendencia | N24: 4e-05 | O24: =IF(I23="","",I23+N24) | P24: =IF(C23=0,"",C23) | Q24: =I23
B25: =I25 | I25: =IF(ISERROR(VLOOKUP(E25,$K$10:$L$14,2,FALSE())*VLOOKUP(G25,$K$18:$L$22,2,FALSE())*VLOOKUP(H25,$K$26:$L$30,2,FALSE())),"",VLOOKUP(E25,$K$10:$L$14,2,FALSE())*VLOOKUP(G25,$K$18:$L$22,2,FALSE())*VLOOKUP(H25,$K$26:$L$30,2,FALSE())) | N25: 3e-05 | O25: =IF(I24="","",I24+N25) | P25: =IF(C24=0,"",C24) | Q25: =I24
B26: =I26 | I26: =IF(ISERROR(VLOOKUP(E26,$K$10:$L$14,2,FALSE())*VLOOKUP(G26,$K$18:$L$22,2,FALSE())*VLOOKUP(H26,$K$26:$L$30,2,FALSE())),"",VLOOKUP(E26,$K$10:$L$14,2,FALSE())*VLOOKUP(G26,$K$18:$L$22,2,FALSE())*VLOOKUP(H26,$K$26:$L$30,2,FALSE())) | K26: Mejora Mucho | L26: 5 | N26: 2e-05 | O26: =IF(I25="","",I25+N26) | P26: =IF(C25=0,"",C25) | Q26: =I25
B27: =I27 | I27: =IF(ISERROR(VLOOKUP(E27,$K$10:$L$14,2,FALSE())*VLOOKUP(G27,$K$18:$L$22,2,FALSE())*VLOOKUP(H27,$K$26:$L$30,2,FALSE())),"",VLOOKUP(E27,$K$10:$L$14,2,FALSE())*VLOOKUP(G27,$K$18:$L$22,2,FALSE())*VLOOKUP(H27,$K$26:$L$30,2,FALSE())) | K27: Mejora | L27: 4 | N27: 1e-05 | O27: =IF(I26="","",I26+N27) | P27: =IF(C26=0,"",C26) | Q27: =I26
B28: =I28 | I28: =IF(ISERROR(VLOOKUP(E28,$K$10:$L$14,2,FALSE())*VLOOKUP(G28,$K$18:$L$22,2,FALSE())*VLOOKUP(H28,$K$26:$L$30,2,FALSE())),"",VLOOKUP(E28,$K$10:$L$14,2,FALSE())*VLOOKUP(G28,$K$18:$L$22,2,FALSE())*VLOOKUP(H28,$K$26:$L$30,2,FALSE())) | K28: Indiferente | L28: 3 | O28: =IF(I27="","",I27+N28) | P28: =IF(C27=0,"",C27) | Q28: =I27
B29: =I29 | I29: =IF(ISERROR(VLOOKUP(E29,$K$10:$L$14,2,FALSE())*VLOOKUP(G29,$K$18:$L$22,2,FALSE())*VLOOKUP(H29,$K$26:$L$30,2,FALSE())),"",VLOOKUP(E29,$K$10:$L$14,2,FALSE())*VLOOKUP(G29,$K$18:$L$22,2,FALSE())*VLOOKUP(H29,$K$26:$L$30,2,FALSE())) | K29: Peor | L29: 2 | O29: =IF(I28="","",I28+N29) | P29: =IF(C28=0,"",C28) | Q29: =I28
B30: =I30 | I30: =IF(ISERROR(VLOOKUP(E30,$K$10:$L$14,2,FALSE())*VLOOKUP(G30,$K$18:$L$22,2,FALSE())*VLOOKUP(H30,$K$26:$L$30,2,FALSE())),"",VLOOKUP(E30,$K$10:$L$14,2,FALSE())*VLOOKUP(G30,$K$18:$L$22,2,FALSE())*VLOOKUP(H30,$K$26:$L$30,2,FALSE())) | K30: Mucho Peor | L30: 1 | O30: =IF(I29="","",I29+N30) | P30: =IF(C29=0,"",C29) | Q30: =I29
C31: La puntuación global de los factores legales | I31: =SUM(I7:I30) -> 339 | O31: =IF(#REF!="","",#REF!+N31) -> #REF! | P31: =IF(#REF!=0,"",#REF!) -> #REF! | Q31: =#REF! -> #REF!
K32: Marco temporal | O32: =IF(I31="","",I31+N32) -> 339 | P32: =IF(C31=0,"",C31) -> La puntuación global de los factores legales | Q32: =I31 -> 339
K34: Definido
K35: Indefinido

Sheet Matriz PESTEL
C1: Nombre de la empresa / y del proyecto
C4: Factores Políticos (P) | E4: Factores Económicos (E) | G4: Factores Sociales (S)
C5: Top 5 Factores Políticos | D5: =SUM(D6:D8) -> 260 | E5: Top 5 Factores Económicos | F5: =SUM(F6:F8) -> 290 | G5: Top 5 Factores Sociales | H5: =SUM(H6:H8) -> 350
B6: 1 | C6: =IF(ISERROR(VLOOKUP(LARGE(F_Pol!$O$8:$O$27,$B6),F_Pol!$O$8:$P$27,2,FALSE())),"",VLOOKUP(LARGE(F_Pol!$O$8:$O$27,$B6),F_Pol!$O$8:$P$27,2,FALSE())) -> Estabilidad política y social en Colombia | D6: =IF(ISERROR(VLOOKUP(LARGE(F_Pol!$O$8:$O$27,$B6),F_Pol!$O$8:$Q$27,3,FALSE())),0,VLOOKUP(LARGE(F_Pol!$O$8:$O$27,$B6),F_Pol!$O$8:$Q$27,3,FALSE())) -> 100 | E6: =IF(ISERROR(VLOOKUP(LARGE(F_Eco!$O$8:$O$27,$B6),F_Eco!$O$8:$P$27,2,FALSE())),"",VLOOKUP(LARGE(F_Eco!$O$8:$O$27,$B6),F_Eco!$O$8:$P$27,2,FALSE())) -> Crecimiento del sector de entretenimiento y ocio | F6: =IF(ISERROR(VLOOKUP(LARGE(F_Eco!$O$8:$O$27,$B6),F_Eco!$O$8:$Q$27,3,FALSE())),0,VLOOKUP(LARGE(F_Eco!$O$8:$O$27,$B6),F_Eco!$O$8:$Q$27,3,FALSE())) -> 125 | G6: =IF(ISERROR(VLOOKUP(LARGE(F_Soc!$O$8:$O$27,$B12),F_Soc!$O$8:$P$27,2,FALSE())),"",VLOOKUP(LARGE(F_Soc!$O$8:$O$27,$B12),F_Soc!$O$8:$P$27,2,FALSE())) -> Urbanización y aislamiento social en ciudades | H6: =IF(ISERROR(VLOOKUP(LARGE(F_Soc!$O$8:$O$27,$B12),F_Soc!$O$8:$Q$27,3,FALSE())),0,VLOOKUP(LARGE(F_Soc!$O$8:$O$27,$B12),F_Soc!$O$8:$Q$27,3,FALSE())) -> 125
